#VRML_SIM R2021a utf8
WorldInfo {
  coordinateSystem "NUE"
}
Viewpoint {
  orientation -0.9079027322889075 0.3926780150651385 0.1466853952745106 0.7806659752004884
  position 1.8628761630534565 1.5286912118335236 1.618855105019924
}
DEF wall_1 Solid {
  translation 0 0 -2.45
  children [
    DEF wall1 Shape {
      appearance Appearance {
        material Material {
          diffuseColor 0 1 0
        }
      }
      geometry Box {
        size 5 0.5 0.1
      }
    }
  ]
  name "solid1"
  boundingObject USE wall1
}
DEF wall_2 Solid {
  translation 0 0 2.45
  children [
    DEF wall2 Shape {
      appearance Appearance {
        material Material {
          diffuseColor 0 1 0
        }
      }
      geometry Box {
        size 5 0.5 0.1
      }
    }
  ]
  name "solid2"
  boundingObject USE wall2
}
DEF wall_3 Solid {
  translation -2.5 0 2.03924e-08
  rotation 0 1 0 -1.5707953071795862
  children [
    DEF wall3 Shape {
      appearance Appearance {
        material Material {
          diffuseColor 0 1 0
        }
      }
      geometry Box {
        size 5 0.5 0.1
      }
    }
  ]
  name "solid3"
  boundingObject USE wall3
}
DEF wall_4 Solid {
  translation 2.53 0 -5.10833e-06
  rotation 0 1 0 -1.5707953071795862
  children [
    DEF wall4 Shape {
      appearance Appearance {
        material Material {
          diffuseColor 0 1 0
        }
      }
      geometry Box {
        size 5 0.5 0.1
      }
    }
  ]
  name "solid4"
  boundingObject USE wall4
}
DirectionalLight {
  direction 0 -1 -0.04
}
Background {
  skyColor [
    1 1 1
  ]
}
DEF cylinder Solid {
  translation -1.93667 0.036076 -0.809887
  rotation -0.09989408884723466 0.09989398884724583 -0.9899708894738103 1.58088
  children [
    DEF cylinder Shape {
      appearance Appearance {
        material Material {
          diffuseColor 1 1 0
        }
      }
      geometry Cylinder {
        height 0.5
        radius 0.19
        subdivision 38
      }
    }
  ]
  name "solidcylinder"
  boundingObject Cylinder {
    height 0.5
    radius 0.19
  }
  physics Physics {
    mass 20
  }
  recognitionColors [
    1 0 0
  ]
}
DEF sphere Solid {
  translation -1.7067664062708217 0.1543039999999996 -0.0680529809382286
  rotation 0.6655473063207855 0.05262576828704214 0.7444980265664544 -1.8758881934886749
  children [
    DEF sphere Shape {
      appearance Appearance {
        material Material {
          diffuseColor 1 1 0
        }
      }
      geometry Sphere {
        radius 0.3
        subdivision 5
      }
    }
  ]
  name "solidsphere"
  boundingObject Sphere {
    radius 0.3
    subdivision 5
  }
  locked TRUE
  recognitionColors [
    1 0 0
  ]
}
DEF floorsolid Solid {
  translation 0 -0.21 0
  children [
    DEF floor Shape {
      appearance Appearance {
        material Material {
          diffuseColor 1 0.4 0.9
        }
      }
      geometry Box {
        size 5 0.1 5
      }
    }
  ]
  name "solid(1)"
  boundingObject Group {
    children [
      DEF floor Shape {
        appearance Appearance {
          material Material {
          }
        }
        geometry Box {
          size 5 0.1 5
        }
      }
    ]
  }
}
Robot {
  translation 1.88086 -0.018264 -0.00376954
  rotation -0.0001866479964595163 -0.999999981031226 5.567829894385091e-05 1.5583
  scale 4 4 4
  children [
    Solid {
      children [
        Shape {
          appearance PBRAppearance {
            baseColor 0.152941 0 0.231373
          }
          geometry Box {
            size 0.03 0.15 0.03
          }
        }
        Camera {
          translation 0.00100013 0.07 0.02
          rotation 0 1 0 -3.1415853071795863
          name "CAM"
          fieldOfView 1
          width 640
          height 640
          lens Lens {
          }
          recognition Recognition {
          }
        }
      ]
      name "solid(4)"
    }
    DistanceSensor {
      translation 0.02 0 0.1
      rotation 0 -1 0 1.27
      children [
        Shape {
          appearance PBRAppearance {
            baseColor 0.952941 0.317647 0
          }
          geometry Box {
            size 0.01 0.01 0.01
          }
        }
      ]
      name "ds_right"
    }
    DistanceSensor {
      translation -0.02 0 0.1
      rotation 0 -1 0 1.87
      children [
        Shape {
          appearance PBRAppearance {
            baseColor 0.952941 0.317647 0
          }
          geometry Box {
            size 0.01 0.01 0.01
          }
        }
      ]
      name "ds_left"
    }
    HingeJoint {
      jointParameters HingeJointParameters {
        anchor 0.06 -3.0304913774206853e-06 0.04999999990816122
      }
      device [
        PositionSensor {
          name "ps_1"
        }
        RotationalMotor {
          name "wheel1"
        }
      ]
      endPoint Solid {
        translation 0.06 -5.88942008225915e-18 0.05
        rotation -1.1780384891872518e-16 0 1 1.5699999999999918
        children [
          DEF robot_wheel Shape {
            appearance PBRAppearance {
              baseColor 0.333333 0 0
            }
            geometry Cylinder {
              height 0.02
              radius 0.04
            }
          }
        ]
        boundingObject USE robot_wheel
        physics Physics {
        }
      }
    }
    HingeJoint {
      jointParameters HingeJointParameters {
        anchor -0.06 -3.03242521797931e-06 0.049999999908043984
      }
      device [
        PositionSensor {
          name "ps_2"
        }
        RotationalMotor {
          name "wheel2"
        }
      ]
      endPoint Solid {
        translation -0.060000000205182695 6.275785602022445e-05 0.04999999585826523
        rotation -1.216790900498237e-07 8.905322138575407e-07 0.999999999999596 1.570003346530196
        children [
          DEF robot_wheel Shape {
            appearance PBRAppearance {
              baseColor 0.333333 0 0
            }
            geometry Cylinder {
              height 0.02
              radius 0.04
            }
          }
        ]
        name "solid(1)"
        boundingObject USE robot_wheel
        physics Physics {
        }
      }
    }
    HingeJoint {
      jointParameters HingeJointParameters {
        position 1667.5852471196663
        anchor 0.05999999999999999 -3.0291739447010566e-06 -0.04999999990824105
      }
      device [
        RotationalMotor {
          name "wheel3"
        }
      ]
      endPoint Solid {
        translation 0.06 -5.528433992167279e-06 -0.04999828830255901
        rotation -0.6910372721554052 0.6904871996489822 -0.21376369105374957 3.5631066958437323
        children [
          DEF robot_wheel Shape {
            appearance PBRAppearance {
              baseColor 0.333333 0 0
            }
            geometry Cylinder {
              height 0.02
              radius 0.04
            }
          }
        ]
        name "solid(2)"
        boundingObject USE robot_wheel
        physics Physics {
        }
      }
    }
    HingeJoint {
      jointParameters HingeJointParameters {
        position 891.2534589852555
        anchor -0.06000000000000001 -3.029297765400883e-06 -0.04999999990823356
      }
      device [
        RotationalMotor {
          name "wheel4"
        }
      ]
      endPoint Solid {
        translation -0.06 -1.289168893096662e-06 -0.05000247954459151
        rotation -0.41913312914774886 0.41879949502963787 0.8055646485625697 1.7845648737114979
        children [
          DEF robot_wheel Shape {
            appearance PBRAppearance {
              baseColor 0.333333 0 0
            }
            geometry Cylinder {
              height 0.02
              radius 0.04
            }
          }
        ]
        name "solid(3)"
        boundingObject USE robot_wheel
        physics Physics {
        }
      }
    }
    DEF botbody Shape {
      appearance PBRAppearance {
        baseColor 0.564706 0 1
        metalness 0
      }
      geometry Box {
        size 0.1 0.05 0.2
      }
    }
  ]
  boundingObject USE botbody
  physics Physics {
  }
  controller "my_controller"
}
